Workbook
Name Excel_BuiltIn_Print_Area_1: #REF!
Name Excel_BuiltIn_Print_Area_1: #REF!
Name Excel_BuiltIn_Print_Area_1: #REF!
Name Excel_BuiltIn_Print_Area_1_1: #REF!
Name Excel_BuiltIn_Print_Area_1_1_1: #REF!
Name Excel_BuiltIn_Print_Area_4: #REF!
Name Excel_BuiltIn_Print_Area_4_1: #REF!

Sheet CS
B2: COATING SCHEDULE | W2: Customer code
B3: Customer | F3: NITORI-HO CHI MINH | M3: No. | O3: : NTR 001 | W3: =VLOOKUP(F3,Customer!A:C,2,0) -> 1200001169
B4: Substrate Type | F4: BEECH WOOD | M4: Date / Rev./ Page | O4: : 09/10/2026
B5: Product Item | F5: TABLE
B6: Positioning | F6: Interior | M6: Finishing Condition Recommended
B7: Finishing System | F7: WATERBASED | M7: MC wood | O7: : 8-12%
B8: Gloss Level | F8: 15±5 SHEEN | M8: Room humidity | O8: : 40-80 %
B9: Reference | M9: Room temp. | O9: : 25 – 40°C
B11: No. | C11: Application Step | F11: Product Code | K11: Mixing Ratio | L11: Visco | N11: CA (g/m2) | O11: Application Method | R11: Drying Time Recommended | U11: Min | V11: Max | W11: App step | X11: Product | Y11: Mix ratio | Z11: App method
C12: SANDING | O12: SANDING PAPER #180-240
B13: 1 | C13: WIPING FILLER | F13: PSV-76000 SB HC MY VN | K13: 10 | N13: =U13&"-"&V13 -> 100-120 | O13: WIPING | R13: 10-15 min | U13: 100 | V13: 120 | W13: =C13 -> WIPING FILLER | X13: =F13 -> PSV-76000 SB HC MY VN | Y13: =K13 -> 10 | Z13: =O13 -> WIPING
F14: PSV-76000 SB HC MY VN | K14: 10 | X14: =F14 -> PSV-76000 SB HC MY VN | Y14: =K14 -> 10
F15: PSV-76000 SB HC MY VN | K15: 60 | X15: =F15 -> PSV-76000 SB HC MY VN | Y15: =K15 -> 60
F16: THPU-71306 01 KD VN | K16: 20 | X16: =F16 -> THPU-71306 01 KD VN | Y16: =K16 -> 20
F17: THPU-71306 01 KD VN | K17: 20 | X17: =F17 -> THPU-71306 01 KD VN | Y17: =K17 -> 20
C18: SANDING | O18: SANDING PAPER #180-240 | X18: =F18 -> 0 | Y18: =K18 -> 0
B19: 2 | C19: SANDING SEALER | F19: PSV-76000 SB HC MY VN | K19: 10 | L19: 40-60" DIN4 | N19: =U19&"-"&V19 -> 100-120 | O19: SPRAY | R19: 60 min OVEN 45-50ºC | U19: 100 | V19: 120 | W19: =C19 -> SANDING SEALER | X19: =F19 -> PSV-76000 SB HC MY VN | Y19: =K19 -> 10 | Z19: =O19 -> SPRAY
F20: PSV-76000 SB HC MY VN | K20: 10 | X20: =F20 -> PSV-76000 SB HC MY VN | Y20: =K20 -> 10
F21: PSV-76000 SB HC MY VN | K21: 60 | X21: =F21 -> PSV-76000 SB HC MY VN | Y21: =K21 -> 60
F22: THPU-71306 01 KD VN | K22: 20 | X22: =F22 -> THPU-71306 01 KD VN | Y22: =K22 -> 20
F23: THPU-71306 01 KD VN | K23: 20 | X23: =F23 -> THPU-71306 01 KD VN | Y23: =K23 -> 20
C24: SANDING | O24: SANDING PAPER #320 | X24: =F24 -> 0 | Y24: =K24 -> 0
B25: 3 | C25: TOP COAT COLOR | F25: PSV-76000 SB HC MY VN | K25: 10 | L25: 40-60" DIN4 | N25: =U25&"-"&V25 -> 100-120 | O25: WIPING | R25: 120 min OVEN 40-45ºC | U25: 100 | V25: 120 | W25: =C25 -> TOP COAT COLOR | X25: =F25 -> PSV-76000 SB HC MY VN | Y25: =K25 -> 10 | Z25: =O25 -> WIPING
F26: PSV-76000 SB HC MY VN | K26: 10 | X26: =F26 -> PSV-76000 SB HC MY VN | Y26: =K26 -> 10
F27: PSV-76000 SB HC MY VN | K27: 60 | X27: =F27 -> PSV-76000 SB HC MY VN | Y27: =K27 -> 60
F28: THPU-71306 01 KD VN | K28: 20 | X28: =F28 -> THPU-71306 01 KD VN | Y28: =K28 -> 20
F29: THPU-71306 01 KD VN | K29: 20 | X29: =F29 -> THPU-71306 01 KD VN | Y29: =K29 -> 20
C30: SANDING | O30: SANDING PAPER #320 | X30: =F30 -> 0 | Y30: =K30 -> 0
B31: 4 | C31: TOP COAT COLOR | F31: PSV-76000 SB HC MY VN | K31: 10 | L31: 40-60" DIN4 | N31: 100-120 | O31: SPRAY | R31: 120 min OVEN 40-45ºC | U31: 100 | V31: 120 | W31: =C31 -> TOP COAT COLOR | X31: =F31 -> PSV-76000 SB HC MY VN | Y31: =K31 -> 10 | Z31: =O31 -> SPRAY
F32: PSV-76000 SB HC MY VN | K32: 10 | X32: =F32 -> PSV-76000 SB HC MY VN | Y32: =K32 -> 10
F33: PSV-76000 SB HC MY VN | K33: 60 | X33: =F33 -> PSV-76000 SB HC MY VN | Y33: =K33 -> 60
F34: THPU-71306 01 KD VN | K34: 20 | X34: =F34 -> THPU-71306 01 KD VN | Y34: =K34 -> 20
F35: THPU-71306 01 KD VN | K35: 20 | X35: =F35 -> THPU-71306 01 KD VN | Y35: =K35 -> 20
C36: SANDING | O36: SANDING PAPER #320 | X36: =F36 -> 0 | Y36: =K36 -> 0
B37: 5 | C37: TOP COAT COLOR | F37: PSV-76000 SB HC MY VN | K37: 10 | L37: 40-60" DIN4 | N37: =U37&"-"&V37 -> 100-120 | O37: WIPING | R37: 120 min OVEN 40-45ºC | U37: 100 | V37: 120 | W37: =C37 -> TOP COAT COLOR | X37: =F37 -> PSV-76000 SB HC MY VN | Y37: =K37 -> 10 | Z37: =O37 -> WIPING
F38: PSV-76000 SB HC MY VN | K38: 10 | X38: =F38 -> PSV-76000 SB HC MY VN | Y38: =K38 -> 10
F39: PSV-76000 SB HC MY VN | K39: 60 | X39: =F39 -> PSV-76000 SB HC MY VN | Y39: =K39 -> 60
F40: THPU-71306 01 KD VN | K40: 20 | X40: =F40 -> THPU-71306 01 KD VN | Y40: =K40 -> 20
F41: THPU-71306 01 KD VN | K41: 20 | X41: =F41 -> THPU-71306 01 KD VN | Y41: =K41 -> 20
C42: SANDING | O42: SANDING PAPER #320 | X42: =F42 -> 0 | Y42: =K42 -> 0
...

Sheet CC
A1: COATING COST CALCULATION
A2: Date : | B2: =CS!O4 -> : 09/10/2026 | R2: customer code
A3: Customer Name | B3: =CS!F3 -> NITORI-HO CHI MINH | R3: =CS!W3 -> 1200001169
A4: Product Item : | B4: =CS!F5 -> TABLE | C4: Color: | D4: SW 90 | I4: Substrate Type: | K4: =CS!F4 -> BEECH WOOD
A5: Finishing System : | B5: =CS!F7 -> WATERBASED | C5: Sheen: | D5: =CS!F8 -> 15±5 SHEEN
A6: Item | B6: Product type | C6: Price (VND/Ltr) | E6: Mixing Ratio | F6: Mixed Price (VND/Ltr set) | G6: Application | H6: Coating Amount (g/m2) | I6: Application Efficiency | J6: CA + Loss (g/m2) | K6: Coverage (m2/Ltr/kg) | L6: Coating Cost (vnd/m2) | P6: Consumption of total mixture for 2000m2 (kg) | Q6: Consumption of each component for 2000m2 (kg) | R6: Cust&product | S6: Price/nett
A7: =CS!W13 -> WIPING FILLER | B7: =CS!X13 -> PSV-76000 SB HC MY VN | C7: =S7 -> 543000 | E7: =CS!Y13 -> 10 | F7: =IFERROR(((C7*E7)+(C8*E8)+(C9*E9)+(C10*E10)+(C11*E11))/(E7+E8+E9+E10+E11),0) -> 379333.33 | G7: =CS!Z13 -> WIPING | H7: =(CS!U13+CS!V13)/2 -> 110 | I7: =VLOOKUP(G7,'app-method'!A:B,2,0) -> 0.35 | J7: =(1/I7)*H7 -> 314.28571 | K7: =1000/J7 -> 3.1818182 | L7: =J7*F7/1000 -> 119219.05 | P7: =J7*2000/1000 -> 628.57143 | Q7: =P7*E7/100 -> 62.857143 | R7: =$R$3&B7 -> 1200001169PSV-76000 SB HC MY VN | S7: =IFERROR(VLOOKUP(R7,quotation!E:J,6,0),0) -> 543000
B8: =CS!X14 -> PSV-76000 SB HC MY VN | C8: =S8 -> 543000 | E8: =CS!Y14 -> 10 | R8: =$R$3&B8 -> 1200001169PSV-76000 SB HC MY VN | S8: =IFERROR(VLOOKUP(R8,quotation!E:J,6,0),0) -> 543000
B9: =CS!X15 -> PSV-76000 SB HC MY VN | C9: =S9 -> 543000 | E9: =CS!Y15 -> 60 | R9: =$R$3&B9 -> 1200001169PSV-76000 SB HC MY VN | S9: =IFERROR(VLOOKUP(R9,quotation!E:J,6,0),0) -> 543000
B10: =CS!X16 -> THPU-71306 01 KD VN | C10: =S10 -> 52000 | E10: =CS!Y16 -> 20 | R10: =$R$3&B10 -> 1200001169THPU-71306 01 KD VN | S10: =IFERROR(VLOOKUP(R10,quotation!E:J,6,0),0) -> 52000
B11: =CS!X17 -> THPU-71306 01 KD VN | C11: =S11 -> 52000 | E11: =CS!Y17 -> 20 | Q11: =P7*E11/100 -> 125.71429 | R11: =$R$3&B11 -> 1200001169THPU-71306 01 KD VN | S11: =IFERROR(VLOOKUP(R11,quotation!E:J,6,0),0) -> 52000
A12: =CS!W19 -> SANDING SEALER | B12: =CS!X19 -> PSV-76000 SB HC MY VN | C12: =S12 -> 543000 | E12: =CS!Y19 -> 10 | F12: =IFERROR(((C12*E12)+(C13*E13)+(C14*E14)+(C15*E15)+(C16*E16))/(E12+E13+E14+E15+E16),0) -> 379333.33 | G12: =CS!Z19 -> SPRAY | H12: =(CS!U19+CS!V19)/2 -> 110 | I12: =VLOOKUP(G12,'app-method'!A:B,2,0) -> 0.6 | J12: =(1/I12)*H12 -> 183.33333 | K12: =1000/J12 -> 5.4545455 | L12: =J12*F12/1000 -> 69544.444 | P12: =J12*2000/1000 -> 366.66667 | Q12: =P12*E12/100 -> 36.666667 | R12: =$R$3&B12 -> 1200001169PSV-76000 SB HC MY VN | S12: =IFERROR(VLOOKUP(R12,quotation!E:J,6,0),0) -> 543000
B13: =CS!X20 -> PSV-76000 SB HC MY VN | C13: =S13 -> 543000 | E13: =CS!Y20 -> 10 | Q13: =P12*E13/100 -> 36.666667 | R13: =$R$3&B13 -> 1200001169PSV-76000 SB HC MY VN | S13: =IFERROR(VLOOKUP(R13,quotation!E:J,6,0),0) -> 543000
B14: =CS!X21 -> PSV-76000 SB HC MY VN | C14: =S14 -> 543000 | E14: =CS!Y21 -> 60 | Q14: =P12*E14/100 -> 220 | R14: =$R$3&B14 -> 1200001169PSV-76000 SB HC MY VN | S14: =IFERROR(VLOOKUP(R14,quotation!E:J,6,0),0) -> 543000
B15: =CS!X22 -> THPU-71306 01 KD VN | C15: =S15 -> 52000 | E15: =CS!Y22 -> 20 | Q15: =P12*E15/100 -> 73.333333 | R15: =$R$3&B15 -> 1200001169THPU-71306 01 KD VN | S15: =IFERROR(VLOOKUP(R15,quotation!E:J,6,0),0) -> 52000
B16: =CS!X23 -> THPU-71306 01 KD VN | C16: =S16 -> 52000 | E16: =CS!Y23 -> 20 | Q16: =P12*E16/100 -> 73.333333 | R16: =$R$3&B16 -> 1200001169THPU-71306 01 KD VN | S16: =IFERROR(VLOOKUP(R16,quotation!E:J,6,0),0) -> 52000
A17: =CS!W25 -> TOP COAT COLOR | B17: =CS!X25 -> PSV-76000 SB HC MY VN | C17: =S17 -> 543000 | E17: =CS!Y25 -> 10 | F17: =IFERROR(((C17*E17)+(C18*E18)+(C19*E19)+(C20*E20)+(C21*E21))/(E17+E18+E19+E20+E21),0) -> 379333.33 | G17: =CS!Z25 -> WIPING | H17: =(CS!U25+CS!V25)/2 -> 110 | I17: =VLOOKUP(G17,'app-method'!A:B,2,0) -> 0.35 | J17: =(1/I17)*H17 -> 314.28571 | K17: =1000/J17 -> 3.1818182 | L17: =J17*F17/1000 -> 119219.05 | P17: =J17*2000/1000 -> 628.57143 | Q17: =P17*E17/100 -> 62.857143 | R17: =$R$3&B17 -> 1200001169PSV-76000 SB HC MY VN | S17: =IFERROR(VLOOKUP(R17,quotation!E:J,6,0),0) -> 543000
B18: =CS!X26 -> PSV-76000 SB HC MY VN | C18: =S18 -> 543000 | E18: =CS!Y26 -> 10 | Q18: =P17*E18/100 -> 62.857143 | R18: =$R$3&B18 -> 1200001169PSV-76000 SB HC MY VN | S18: =IFERROR(VLOOKUP(R18,quotation!E:J,6,0),0) -> 543000
B19: =CS!X27 -> PSV-76000 SB HC MY VN | C19: =S19 -> 543000 | E19: =CS!Y27 -> 60 | Q19: =P17*E19/100 -> 377.14286 | R19: =$R$3&B19 -> 1200001169PSV-76000 SB HC MY VN | S19: =IFERROR(VLOOKUP(R19,quotation!E:J,6,0),0) -> 543000
B20: =CS!X28 -> THPU-71306 01 KD VN | C20: =S20 -> 52000 | E20: =CS!Y28 -> 20 | Q20: =P17*E20/100 -> 125.71429 | R20: =$R$3&B20 -> 1200001169THPU-71306 01 KD VN | S20: =IFERROR(VLOOKUP(R20,quotation!E:J,6,0),0) -> 52000
B21: =CS!X29 -> THPU-71306 01 KD VN | C21: =S21 -> 52000 | E21: =CS!Y29 -> 20 | Q21: =P17*E21/100 -> 125.71429 | R21: =$R$3&B21 -> 1200001169THPU-71306 01 KD VN | S21: =IFERROR(VLOOKUP(R21,quotation!E:J,6,0),0) -> 52000
A22: =CS!W31 -> TOP COAT COLOR | B22: =CS!X31 -> PSV-76000 SB HC MY VN | C22: =S22 -> 543000 | E22: =CS!Y31 -> 10 | F22: =IFERROR(((C22*E22)+(C23*E23)+(C24*E24)+(C25*E25)+(C26*E26))/(E22+E23+E24+E25+E26),0) -> 379333.33 | G22: =CS!Z31 -> SPRAY | H22: =(CS!U31+CS!V31)/2 -> 110 | I22: =VLOOKUP(G22,'app-method'!A:B,2,0) -> 0.6 | J22: =(1/I22)*H22 -> 183.33333 | K22: =1000/J22 -> 5.4545455 | L22: =J22*F22/1000 -> 69544.444 | P22: =J22*2000/1000 -> 366.66667 | Q22: =P22*E22/100 -> 36.666667 | R22: =$R$3&B22 -> 1200001169PSV-76000 SB HC MY VN | S22: =IFERROR(VLOOKUP(R22,quotation!E:J,6,0),0) -> 543000
B23: =CS!X32 -> PSV-76000 SB HC MY VN | C23: =S23 -> 543000 | E23: =CS!Y32 -> 10 | Q23: =P22*E23/100 -> 36.666667 | R23: =$R$3&B23 -> 1200001169PSV-76000 SB HC MY VN | S23: =IFERROR(VLOOKUP(R23,quotation!E:J,6,0),0) -> 543000
B24: =CS!X33 -> PSV-76000 SB HC MY VN | C24: =S24 -> 543000 | E24: =CS!Y33 -> 60 | Q24: =P22*E24/100 -> 220 | R24: =$R$3&B24 -> 1200001169PSV-76000 SB HC MY VN | S24: =IFERROR(VLOOKUP(R24,quotation!E:J,6,0),0) -> 543000
B25: =CS!X34 -> THPU-71306 01 KD VN | C25: =S25 -> 52000 | E25: =CS!Y34 -> 20 | Q25: =P22*E25/100 -> 73.333333 | R25: =$R$3&B25 -> 1200001169THPU-71306 01 KD VN | S25: =IFERROR(VLOOKUP(R25,quotation!E:J,6,0),0) -> 52000
B26: =CS!X35 -> THPU-71306 01 KD VN | C26: =S26 -> 52000 | E26: =CS!Y35 -> 20 | Q26: =P22*E26/100 -> 73.333333 | R26: =$R$3&B26 -> 1200001169THPU-71306 01 KD VN | S26: =IFERROR(VLOOKUP(R26,quotation!E:J,6,0),0) -> 52000
A27: =CS!W37 -> TOP COAT COLOR | B27: =CS!X37 -> PSV-76000 SB HC MY VN | C27: =S27 -> 543000 | E27: =CS!Y37 -> 10 | F27: =IFERROR(((C27*E27)+(C28*E28)+(C29*E29)+(C30*E30)+(C31*E31))/(E27+E28+E29+E30+E31),0) -> 379333.33 | G27: =CS!Z37 -> WIPING | H27: =(CS!U37+CS!V37)/2 -> 110 | I27: =VLOOKUP(G27,'app-method'!A:B,2,0) -> 0.35 | J27: =(1/I27)*H27 -> 314.28571 | K27: =1000/J27 -> 3.1818182 | L27: =J27*F27/1000 -> 119219.05 | P27: =J27*2000/1000 -> 628.57143 | Q27: =P27*E27/100 -> 62.857143 | R27: =$R$3&B27 -> 1200001169PSV-76000 SB HC MY VN | S27: =IFERROR(VLOOKUP(R27,quotation!E:J,6,0),0) -> 543000
B28: =CS!X38 -> PSV-76000 SB HC MY VN | C28: =S28 -> 543000 | E28: =CS!Y38 -> 10 | Q28: =P27*E28/100 -> 62.857143 | R28: =$R$3&B28 -> 1200001169PSV-76000 SB HC MY VN | S28: =IFERROR(VLOOKUP(R28,quotation!E:J,6,0),0) -> 543000
B29: =CS!X39 -> PSV-76000 SB HC MY VN | C29: =S29 -> 543000 | E29: =CS!Y39 -> 60 | Q29: =P27*E29/100 -> 377.14286 | R29: =$R$3&B29 -> 1200001169PSV-76000 SB HC MY VN | S29: =IFERROR(VLOOKUP(R29,quotation!E:J,6,0),0) -> 543000
B30: =CS!X40 -> THPU-71306 01 KD VN | C30: =S30 -> 52000 | E30: =CS!Y40 -> 20 | Q30: =P27*E30/100 -> 125.71429 | R30: =$R$3&B30 -> 1200001169THPU-71306 01 KD VN | S30: =IFERROR(VLOOKUP(R30,quotation!E:J,6,0),0) -> 52000
B31: =CS!X41 -> THPU-71306 01 KD VN | C31: =S31 -> 52000 | E31: =CS!Y41 -> 20 | Q31: =P27*E31/100 -> 125.71429 | R31: =$R$3&B31 -> 1200001169THPU-71306 01 KD VN | S31: =IFERROR(VLOOKUP(R31,quotation!E:J,6,0),0) -> 52000
A32: =CS!W43 -> STAIN + EQUALIZER/ STAIN + SỬA GỖ | B32: =CS!X43 -> PSV-76000 SB HC MY VN | C32: =S32 -> 543000 | E32: =CS!Y43 -> 10 | F32: =IFERROR(((C32*E32)+(C33*E33)+(C34*E34)+(C35*E35)+(C36*E36))/(E32+E33+E34+E35+E36),0) -> 379333.33 | G32: =CS!Z43 -> SPRAY | H32: =(CS!U43+CS!V43)/2 -> 110 | I32: =VLOOKUP(G32,'app-method'!A:B,2,0) -> 0.6 | J32: =(1/I32)*H32 -> 183.33333 | K32: =1000/J32 -> 5.4545455 | L32: =J32*F32/1000 -> 69544.444 | P32: =J32*2000/1000 -> 366.66667 | Q32: =P32*E32/100 -> 36.666667 | R32: =$R$3&B32 -> 1200001169PSV-76000 SB HC MY VN | S32: =IFERROR(VLOOKUP(R32,quotation!E:J,6,0),0) -> 543000
B33: =CS!X44 -> PSV-76000 SB HC MY VN | C33: =S33 -> 543000 | E33: =CS!Y44 -> 10 | Q33: =P32*E33/100 -> 36.666667 | R33: =$R$3&B33 -> 1200001169PSV-76000 SB HC MY VN | S33: =IFERROR(VLOOKUP(R33,quotation!E:J,6,0),0) -> 543000
B34: =CS!X45 -> PSV-76000 SB HC MY VN | C34: =S34 -> 543000 | E34: =CS!Y45 -> 60 | Q34: =P32*E34/100 -> 220 | R34: =$R$3&B34 -> 1200001169PSV-76000 SB HC MY VN | S34: =IFERROR(VLOOKUP(R34,quotation!E:J,6,0),0) -> 543000
B35: =CS!X46 -> THPU-71306 01 KD VN | C35: =S35 -> 52000 | E35: =CS!Y46 -> 20 | Q35: =P32*E35/100 -> 73.333333 | R35: =$R$3&B35 -> 1200001169THPU-71306 01 KD VN | S35: =IFERROR(VLOOKUP(R35,quotation!E:J,6,0),0) -> 52000
B36: =CS!X47 -> THPU-71306 01 KD VN | C36: =S36 -> 52000 | E36: =CS!Y47 -> 20 | Q36: =P32*E36/100 -> 73.333333 | R36: =$R$3&B36 -> 1200001169THPU-71306 01 KD VN | S36: =IFERROR(VLOOKUP(R36,quotation!E:J,6,0),0) -> 52000
A37: =CS!W49 -> TOP COAT COLOR | B37: =CS!X49 -> PSV-76000 SB HC MY VN | C37: =S37 -> 543000 | E37: =CS!Y49 -> 10 | F37: =IFERROR(((C37*E37)+(C38*E38)+(C39*E39)+(C40*E40)+(C41*E41))/(E37+E38+E39+E40+E41),0) -> 379333.33 | G37: =CS!Z49 -> WIPING | H37: =(CS!U49+CS!V49)/2 -> 110 | I37: =VLOOKUP(G37,'app-method'!A:B,2,0) -> 0.35 | J37: =(1/I37)*H37 -> 314.28571 | K37: =1000/J37 -> 3.1818182 | L37: =J37*F37/1000 -> 119219.05 | P37: =J37*2000/1000 -> 628.57143 | Q37: =P37*E37/100 -> 62.857143 | R37: =$R$3&B37 -> 1200001169PSV-76000 SB HC MY VN | S37: =IFERROR(VLOOKUP(R37,quotation!E:J,6,0),0) -> 543000
B38: =CS!X50 -> PSV-76000 SB HC MY VN | C38: =S38 -> 543000 | E38: =CS!Y50 -> 10 | Q38: =P37*E38/100 -> 62.857143 | R38: =$R$3&B38 -> 1200001169PSV-76000 SB HC MY VN | S38: =IFERROR(VLOOKUP(R38,quotation!E:J,6,0),0) -> 543000
B39: =CS!X51 -> PSV-76000 SB HC MY VN | C39: =S39 -> 543000 | E39: =CS!Y51 -> 60 | Q39: =P37*E39/100 -> 377.14286 | R39: =$R$3&B39 -> 1200001169PSV-76000 SB HC MY VN | S39: =IFERROR(VLOOKUP(R39,quotation!E:J,6,0),0) -> 543000
B40: =CS!X52 -> THPU-71306 01 KD VN | C40: =S40 -> 52000 | E40: =CS!Y52 -> 20 | Q40: =P37*E40/100 -> 125.71429 | R40: =$R$3&B40 -> 1200001169THPU-71306 01 KD VN | S40: =IFERROR(VLOOKUP(R40,quotation!E:J,6,0),0) -> 52000
...

Sheet Application Step Master
A1: SANDING
A2: CHỐNG XÌ DẦU
A3: STAIN + EQUALIZER/ STAIN + SỬA GỖ
A4: SEALER/ LÓT TRONG
A5: SANDING
A6: GLAZE
A7: COLORING
A8: TOP COAT

Sheet app-method
A1: APLICATION | B1: Application Efficiency
A2: WIPING | B2: 0.35
A3: SPRAY | B3: 0.6

Sheet Customer
A1: Short Name | B1: Customer | C1: Name
A2: 1 | B2: 1100000006 | C2: CÔNG TY TNHH
A3: 2 | B3: 1200000001 | C3: Công Ty Cổ Phần Xây Dựng Kiến Trúc AA
A4: 3 | B4: 1200000002 | C4: Công Ty TNHH Nội Thất Toàn Thiên Ấn
A5: 4 | B5: 1200000003 | C5: Công Ty Cổ Phần Chế Biến Gỗ Pisico Đồng An
A6: 5 | B6: 1200000004 | C6: Công Ty TNHH TM DV XD Đông Nam á
A7: 6 | B7: 1200000005 | C7: Công Ty TNHH In Nam Ấn
A8: 7 | B8: 1200000006 | C8: Công Ty TNHH Phát Triển Mộc Nội Thất Quyền Anh
A9: 8 | B9: 1200000007 | C9: Công Ty TNHH ARDEX Việt Nam
A10: 9 | B10: 1200000008 | C10: Công Ty Cổ Phần Hà Ân
A11: 10 | B11: 1200000009 | C11: Công Ty TNHH Nội Thất AAA
A12: 11 | B12: 1200000010 | C12: Công Ty TNHH Hoàng Kiều Anh
A13: 12 | B13: 1200000011 | C13: Công Ty TNHH TMDV Trang Trí Nội Thất Việt Anh
... A518: 520 | B518: 1200001168 | C518: NGUYỄN VĂN XUYÊN
A519: NITORI-HO CHI MINH | B519: 1200001169 | C519: DOANH NGHIỆP CHẾ XUẤT NITORI VIỆT NAM
A520: 522 | B520: 1200001170 | C520: CÔNG TY TNHH MTV NHƯ ANH PHÁT
A521: 523 | B521: 1200001173 | C521: CÔNG TY TNHH MỘT THÀNH VIÊN SẢN XUẤT THƯƠNG MẠI DỊCH VỤ K.C.S
A522: 524 | B522: 1200001174 | C522: CÔNG TY CỔ PHẦN THƯƠNG MẠI PT PHÚC THỊNH
A523: 525 | B523: 1200001175 | C523: CÔNG TY TNHH SẢN XUẤT THƯƠNG MẠI DIHAFO – CHI NHÁNH BÌNH DƯƠNG
A524: 526 | B524: 1200001177 | C524: CÔNG TY TNHH NỘI THẤT KIM PHÁT
A525: 527 | B525: 1200001178 | C525: CÔNG TY TNHH NỘI THẤT HƯNG THỊNH PHÁT
A526: 528 | B526: 1200001180 | C526: CÔNG TY TNHH MỘT THÀNH VIÊN VITANA
A527: 529 | B527: 1200001181 | C527: CÔNG TY TNHH MINH THÀNH
A528: 530 | B528: 1200001184 | C528: CÔNG TY CỔ PHẦN DNG FURNITURE
A529: 531 | B529: 1200001186 | C529: CÔNG TY TNHH ĐỒ GỖ NỘI THẤT THÁI DƯƠNG
A530: 532 | B530: 1200001187 | C530: CÔNG TY TNHH MỘT THÀNH VIÊN TMDV SX NAM PHÁT
A531: 533 | B531: 1200001188 | C531: CÔNG TY TNHH HƯNG GIA THỊNH FURNITURE
... A540: 542 | B540: 1200001206 | C540: CÔNG TY TNHH SX TM & DV CSZ-OCEAN

Sheet quotation
A1: Sold-to | B1: Name of Sold-to | C1: Material | D1: Description | E1: Cust&Name | F1: Name without Pack | G1: Pack | H1: Nett | I1: Price | J1: Price/nett
A2: 1200001152 | B2: ÂU DƯƠNG THIÊN NGA | C2: 100000497 | D2: PUL-51339 CLEAR 10 VN-20LP | E2: =A2&F2 -> 1200001152PUL-51339 CLEAR 10 VN | F2: PUL-51339 CLEAR 10 VN | G2: 20LP | H2: =VLOOKUP(G2,'packing mapping'!A:B,2,0) -> 20 | I2: 2258000 | J2: =I2/H2 -> 112900
A3: 1200001152 | B3: ÂU DƯƠNG THIÊN NGA | C3: 100000884 | D3: THPU-71306 ST VN-20LJ | E3: =A3&F3 -> 1200001152THPU-71306 ST VN | F3: THPU-71306 ST VN | G3: 20LJ | H3: =VLOOKUP(G3,'packing mapping'!A:B,2,0) -> 20 | I3: 1029600 | J3: =I3/H3 -> 51480
A4: 1200001152 | B4: ÂU DƯƠNG THIÊN NGA | C4: 100002436 | D4: PUH-56135 S VN-20KP | E4: =A4&F4 -> 1200001152PUH-56135 S VN | F4: PUH-56135 S VN | G4: 20KP | H4: =VLOOKUP(G4,'packing mapping'!A:B,2,0) -> 20 | I4: 1610800 | J4: =I4/H4 -> 80540
A5: 1200001152 | B5: ÂU DƯƠNG THIÊN NGA | C5: 100002438 | D5: PUH-56139 VN-20KP | E5: =A5&F5 -> 1200001152PUH-56139 VN | F5: PUH-56139 VN | G5: 20KP | H5: =VLOOKUP(G5,'packing mapping'!A:B,2,0) -> 20 | I5: 1873200 | J5: =I5/H5 -> 93660
A6: 1200001152 | B6: ÂU DƯƠNG THIÊN NGA | C6: 100002527 | D6: PUSS-51235 VN-20KP | E6: =A6&F6 -> 1200001152PUSS-51235 VN | F6: PUSS-51235 VN | G6: 20KP | H6: =VLOOKUP(G6,'packing mapping'!A:B,2,0) -> 20 | I6: 1757800 | J6: =I6/H6 -> 87890
A7: 1200001152 | B7: ÂU DƯƠNG THIÊN NGA | C7: 100006629 | D7: PUL-51339 SR CLEAR 10 VN-18KP | E7: =A7&F7 -> 1200001152PUL-51339 SR CLEAR 10 VN | F7: PUL-51339 SR CLEAR 10 VN | G7: 18KP | H7: =VLOOKUP(G7,'packing mapping'!A:B,2,0) -> 18 | I7: 3177180 | J7: =I7/H7 -> 176510
A8: 1200000019 | B8: Công Ty Cổ Phần An Phát Cường | C8: 100000109 | D8: GZPU-21500 RU BASE VN-18KP | E8: =A8&F8 -> 1200000019GZPU-21500 RU BASE VN | F8: GZPU-21500 RU BASE VN | G8: 18KP | H8: =VLOOKUP(G8,'packing mapping'!A:B,2,0) -> 18 | I8: 2990700 | J8: =I8/H8 -> 166150
A9: 1200000019 | B9: Công Ty Cổ Phần An Phát Cường | C9: 100000122 | D9: MEP-12003 BROWN KI VN-18KP | E9: =A9&F9 -> 1200000019MEP-12003 BROWN KI VN | F9: MEP-12003 BROWN KI VN | G9: 18KP | H9: =VLOOKUP(G9,'packing mapping'!A:B,2,0) -> 18 | I9: 1507680 | J9: =I9/H9 -> 83760
A10: 1200000019 | B10: Công Ty Cổ Phần An Phát Cường | C10: 100000123 | D10: MEP-12003 CLEAR BASE VN-18KP | E10: =A10&F10 -> 1200000019MEP-12003 CLEAR BASE VN | F10: MEP-12003 CLEAR BASE VN | G10: 18KP | H10: =VLOOKUP(G10,'packing mapping'!A:B,2,0) -> 18 | I10: 1726560 | J10: =I10/H10 -> 95920
A11: 1200000019 | B11: Công Ty Cổ Phần An Phát Cường | C11: 100000124 | D11: MEP-12003 GREY VN-18KP | E11: =A11&F11 -> 1200000019MEP-12003 GREY VN | F11: MEP-12003 GREY VN | G11: 18KP | H11: =VLOOKUP(G11,'packing mapping'!A:B,2,0) -> 18 | I11: 1788840 | J11: =I11/H11 -> 99380
A12: 1200000019 | B12: Công Ty Cổ Phần An Phát Cường | C12: 100000210 | D12: PCA-31100 BLACK PASTE VN-4K | E12: =A12&F12 -> 1200000019PCA-31100 BLACK PASTE VN | F12: PCA-31100 BLACK PASTE VN | G12: 4K | H12: =VLOOKUP(G12,'packing mapping'!A:B,2,0) -> 4 | I12: 1442080 | J12: =I12/H12 -> 360520
A13: 1200000019 | B13: Công Ty Cổ Phần An Phát Cường | C13: 100000273 | D13: PCA-31100 WHITE PASTE VN-4K | E13: =A13&F13 -> 1200000019PCA-31100 WHITE PASTE VN | F13: PCA-31100 WHITE PASTE VN | G13: 4K | H13: =VLOOKUP(G13,'packing mapping'!A:B,2,0) -> 4 | I13: 1138360 | J13: =I13/H13 -> 284590
... A2676: 1200001168 | B2676: NGUYỄN VĂN XUYÊN | C2676: 100004513 | D2676: PUH-56141 VN-20KP | E2676: =A2676&F2676 -> 1200001168PUH-56141 VN | F2676: PUH-56141 VN | G2676: 20KP | H2676: =VLOOKUP(G2676,'packing mapping'!A:B,2,0) -> 20 | I2676: 2336000 | J2676: =I2676/H2676 -> 116800

Sheet packing mapping
A1: 20LP | B1: 20
A2: 20LJ | B2: 20
A3: 20KP | B3: 20
A4: 18KP | B4: 18
A5: 4K | B5: 4
A6: 200LK | B6: 200
A7: 18KJ | B7: 18
A8: 5K | B8: 5
A9: 2K | B9: 2
A10: 4L | B10: 4
A11: 200KB | B11: 200
A12: 16KP | B12: 16
... A33: 210KB | B33: 210
